[2023-11-11 09:56:40,433: INFO: utils: NumExpr defaulting to 4 threads.]
[2023-11-11 09:56:45,040: WARNING: _internal:  * Running on all addresses.
   WARNING: This is a development server. Do not use it in a production deployment.]
[2023-11-11 09:56:45,040: INFO: _internal:  * Running on http://192.168.1.216:80/ (Press CTRL+C to quit)]
[2023-11-11 09:57:04,995: INFO: _internal: 192.168.1.216 - - [11/Nov/2023 09:57:04] "GET / HTTP/1.1" 200 -]
[2023-11-11 09:58:19,666: ERROR: app: Exception on /predict [POST]]
Traceback (most recent call last):
  File "C:\Users\anink\anaconda3\lib\site-packages\flask\app.py", line 2447, in wsgi_app
    response = self.full_dispatch_request()
  File "C:\Users\anink\anaconda3\lib\site-packages\flask\app.py", line 1952, in full_dispatch_request
    rv = self.handle_user_exception(e)
  File "C:\Users\anink\anaconda3\lib\site-packages\flask_cors\extension.py", line 176, in wrapped_function
    return cors_after_request(app.make_response(f(*args, **kwargs)))
  File "C:\Users\anink\anaconda3\lib\site-packages\flask\app.py", line 1821, in handle_user_exception
    reraise(exc_type, exc_value, tb)
  File "C:\Users\anink\anaconda3\lib\site-packages\flask\_compat.py", line 39, in reraise
    raise value
  File "C:\Users\anink\anaconda3\lib\site-packages\flask\app.py", line 1950, in full_dispatch_request
    rv = self.dispatch_request()
  File "C:\Users\anink\anaconda3\lib\site-packages\flask\app.py", line 1936, in dispatch_request
    return self.view_functions[rule.endpoint](**req.view_args)
  File "C:\Users\anink\anaconda3\lib\site-packages\flask_cors\decorator.py", line 130, in wrapped_function
    resp = make_response(f(*args, **kwargs))
  File "C:\Users\anink\OneDrive\Documents\books\chicken\Chicken-Disease-Classification-Projects-val\app.py", line 40, in predictRoute
    result = clApp.classifier.predict()
  File "c:\users\anink\onedrive\documents\books\chicken\chicken-disease-classification-projects-val\src\cnnClassifier\pipeline\predict.py", line 16, in predict
    model = load_model(os.path.join("artifacts","training", "model.h5"))
  File "C:\Users\anink\anaconda3\lib\site-packages\keras\src\saving\saving_api.py", line 262, in load_model
    return legacy_sm_saving_lib.load_model(
  File "C:\Users\anink\anaconda3\lib\site-packages\keras\src\utils\traceback_utils.py", line 70, in error_handler
    raise e.with_traceback(filtered_tb) from None
  File "C:\Users\anink\anaconda3\lib\site-packages\keras\src\saving\legacy\save.py", line 234, in load_model
    raise IOError(
OSError: No file or directory found at artifacts\training\model.h5
[2023-11-11 09:58:19,695: INFO: _internal: 192.168.1.216 - - [11/Nov/2023 09:58:19] "[35m[1mPOST /predict HTTP/1.1[0m" 500 -]
[2023-11-11 10:22:18,137: INFO: utils: NumExpr defaulting to 4 threads.]
[2023-11-11 10:22:19,425: WARNING: _internal:  * Running on all addresses.
   WARNING: This is a development server. Do not use it in a production deployment.]
[2023-11-11 10:22:19,441: INFO: _internal:  * Running on http://192.168.1.216:80/ (Press CTRL+C to quit)]
[2023-11-11 10:22:33,977: INFO: _internal: 192.168.1.216 - - [11/Nov/2023 10:22:33] "GET / HTTP/1.1" 200 -]
[2023-11-12 06:54:39,924: INFO: utils: NumExpr defaulting to 4 threads.]
[2023-11-12 06:54:41,784: WARNING: _internal:  * Running on all addresses.
   WARNING: This is a development server. Do not use it in a production deployment.]
[2023-11-12 06:54:41,784: INFO: _internal:  * Running on http://192.168.1.216:80/ (Press CTRL+C to quit)]
[2023-11-12 06:54:51,729: INFO: _internal: 192.168.1.216 - - [12/Nov/2023 06:54:51] "GET / HTTP/1.1" 200 -]
[2023-11-12 06:57:50,078: ERROR: app: Exception on /predict [POST]]
Traceback (most recent call last):
  File "C:\Users\anink\anaconda3\lib\site-packages\flask\app.py", line 2447, in wsgi_app
    response = self.full_dispatch_request()
  File "C:\Users\anink\anaconda3\lib\site-packages\flask\app.py", line 1952, in full_dispatch_request
    rv = self.handle_user_exception(e)
  File "C:\Users\anink\anaconda3\lib\site-packages\flask_cors\extension.py", line 176, in wrapped_function
    return cors_after_request(app.make_response(f(*args, **kwargs)))
  File "C:\Users\anink\anaconda3\lib\site-packages\flask\app.py", line 1821, in handle_user_exception
    reraise(exc_type, exc_value, tb)
  File "C:\Users\anink\anaconda3\lib\site-packages\flask\_compat.py", line 39, in reraise
    raise value
  File "C:\Users\anink\anaconda3\lib\site-packages\flask\app.py", line 1950, in full_dispatch_request
    rv = self.dispatch_request()
  File "C:\Users\anink\anaconda3\lib\site-packages\flask\app.py", line 1936, in dispatch_request
    return self.view_functions[rule.endpoint](**req.view_args)
  File "C:\Users\anink\anaconda3\lib\site-packages\flask_cors\decorator.py", line 130, in wrapped_function
    resp = make_response(f(*args, **kwargs))
  File "C:\Users\anink\OneDrive\Documents\books\chicken\Chicken-Disease-Classification-Projects-val\app.py", line 40, in predictRoute
    result = clApp.classifier.predict()
  File "c:\users\anink\onedrive\documents\books\chicken\chicken-disease-classification-projects-val\src\cnnClassifier\pipeline\predict.py", line 16, in predict
    model = load_model(os.path.join("artifacts","training", "model.h5"))
  File "C:\Users\anink\anaconda3\lib\site-packages\keras\src\saving\saving_api.py", line 262, in load_model
    return legacy_sm_saving_lib.load_model(
  File "C:\Users\anink\anaconda3\lib\site-packages\keras\src\utils\traceback_utils.py", line 70, in error_handler
    raise e.with_traceback(filtered_tb) from None
  File "C:\Users\anink\anaconda3\lib\site-packages\keras\src\saving\legacy\save.py", line 234, in load_model
    raise IOError(
OSError: No file or directory found at artifacts\training\model.h5
[2023-11-12 06:57:50,143: INFO: _internal: 192.168.1.216 - - [12/Nov/2023 06:57:50] "[35m[1mPOST /predict HTTP/1.1[0m" 500 -]
[2023-11-12 07:02:52,867: INFO: utils: NumExpr defaulting to 4 threads.]
[2023-11-12 07:02:54,006: INFO: main: >>>>>> stage Data Ingestion stage started <<<<<<]
[2023-11-12 07:02:54,012: INFO: common: yaml file: config\config.yaml loaded successfully]
[2023-11-12 07:02:54,020: INFO: common: yaml file: params.yaml loaded successfully]
[2023-11-12 07:02:54,023: INFO: common: created directory at: artifacts]
[2023-11-12 07:02:54,026: INFO: common: created directory at: artifacts/data_ingestion]
[2023-11-12 07:02:56,263: INFO: data_ingestion: artifacts/data_ingestion/data.zip download! with following info: 
Connection: close
Content-Length: 11616915
Cache-Control: max-age=300
Content-Security-Policy: default-src 'none'; style-src 'unsafe-inline'; sandbox
Content-Type: application/zip
ETag: "adf745abc03891fe493c3be264ec012691fe3fa21d861f35a27edbe6d86a76b1"
Strict-Transport-Security: max-age=31536000
X-Content-Type-Options: nosniff
X-Frame-Options: deny
X-XSS-Protection: 1; mode=block
X-GitHub-Request-Id: 3ED4:1001:179F41:1F743E:6550DB0D
Accept-Ranges: bytes
Date: Sun, 12 Nov 2023 14:02:57 GMT
Via: 1.1 varnish
X-Served-By: cache-yyc1430032-YYC
X-Cache: MISS
X-Cache-Hits: 0
X-Timer: S1699797776.487066,VS0,VE1070
Vary: Authorization,Accept-Encoding,Origin
Access-Control-Allow-Origin: *
Cross-Origin-Resource-Policy: cross-origin
X-Fastly-Request-ID: f7ba8dcd8005e14324e4449967012c73dc7ec02b
Expires: Sun, 12 Nov 2023 14:07:57 GMT
Source-Age: 1

]
[2023-11-12 07:02:57,568: INFO: main: >>>>>> stage Data Ingestion stage completed <<<<<<

x==========x]
[2023-11-12 07:02:57,569: INFO: main: *******************]
[2023-11-12 07:02:57,569: INFO: main: >>>>>> stage Prepare base model started <<<<<<]
[2023-11-12 07:02:57,575: INFO: common: yaml file: config\config.yaml loaded successfully]
[2023-11-12 07:02:57,579: INFO: common: yaml file: params.yaml loaded successfully]
[2023-11-12 07:02:57,581: INFO: common: created directory at: artifacts]
[2023-11-12 07:02:57,582: INFO: common: created directory at: artifacts/prepare_base_model]
[2023-11-12 07:03:00,982: WARNING: saving_utils: Compiled the loaded model, but the compiled metrics have yet to be built. `model.compile_metrics` will be empty until you train or evaluate the model.]
[2023-11-12 07:03:01,512: INFO: main: >>>>>> stage Prepare base model completed <<<<<<

x==========x]
[2023-11-12 07:03:01,513: INFO: main: *******************]
[2023-11-12 07:03:01,514: INFO: main: >>>>>> stage Training started <<<<<<]
[2023-11-12 07:03:01,518: INFO: common: yaml file: config\config.yaml loaded successfully]
[2023-11-12 07:03:01,521: INFO: common: yaml file: params.yaml loaded successfully]
[2023-11-12 07:03:01,522: INFO: common: created directory at: artifacts]
[2023-11-12 07:03:01,524: INFO: common: created directory at: artifacts\prepare_callbacks\checkpoint_dir]
[2023-11-12 07:03:01,525: INFO: common: created directory at: artifacts\prepare_callbacks\tensorboard_log_dir]
[2023-11-12 07:03:01,529: ERROR: main: 'WindowsPath' object has no attribute 'endswith']
Traceback (most recent call last):
  File "C:\Users\anink\OneDrive\Documents\books\chicken\Chicken-Disease-Classification-Projects-val\main.py", line 40, in <module>
    model_trainer.main()
  File "c:\users\anink\onedrive\documents\books\chicken\chicken-disease-classification-projects-val\src\cnnClassifier\pipeline\stage_03_training.py", line 19, in main
    callback_list = prepare_callbacks.get_tb_ckpt_callbacks()
  File "c:\users\anink\onedrive\documents\books\chicken\chicken-disease-classification-projects-val\src\cnnClassifier\components\prepare_callbacks.py", line 36, in get_tb_ckpt_callbacks
    self._create_ckpt_callbacks
  File "c:\users\anink\onedrive\documents\books\chicken\chicken-disease-classification-projects-val\src\cnnClassifier\components\prepare_callbacks.py", line 27, in _create_ckpt_callbacks
    return tf.keras.callbacks.ModelCheckpoint(
  File "C:\Users\anink\anaconda3\lib\site-packages\keras\src\callbacks.py", line 1369, in __init__
    if filepath and filepath.endswith(".keras") and options is not None:
AttributeError: 'WindowsPath' object has no attribute 'endswith'
[2023-11-12 07:03:02,382: INFO: _internal: 192.168.1.216 - - [12/Nov/2023 07:03:02] "GET /train HTTP/1.1" 200 -]
[2023-11-12 07:03:02,516: INFO: _internal: 192.168.1.216 - - [12/Nov/2023 07:03:02] "[33mGET /favicon.ico HTTP/1.1[0m" 404 -]
[2023-11-12 07:04:03,211: INFO: utils: NumExpr defaulting to 4 threads.]
[2023-11-12 07:04:04,435: WARNING: _internal:  * Running on all addresses.
   WARNING: This is a development server. Do not use it in a production deployment.]
[2023-11-12 07:04:04,438: INFO: _internal:  * Running on http://192.168.1.216:80/ (Press CTRL+C to quit)]
[2023-11-12 07:04:14,456: INFO: _internal: 192.168.1.216 - - [12/Nov/2023 07:04:14] "GET / HTTP/1.1" 200 -]
[2023-11-12 07:04:43,083: ERROR: app: Exception on /predict [POST]]
Traceback (most recent call last):
  File "C:\Users\anink\anaconda3\lib\site-packages\flask\app.py", line 2447, in wsgi_app
    response = self.full_dispatch_request()
  File "C:\Users\anink\anaconda3\lib\site-packages\flask\app.py", line 1952, in full_dispatch_request
    rv = self.handle_user_exception(e)
  File "C:\Users\anink\anaconda3\lib\site-packages\flask_cors\extension.py", line 176, in wrapped_function
    return cors_after_request(app.make_response(f(*args, **kwargs)))
  File "C:\Users\anink\anaconda3\lib\site-packages\flask\app.py", line 1821, in handle_user_exception
    reraise(exc_type, exc_value, tb)
  File "C:\Users\anink\anaconda3\lib\site-packages\flask\_compat.py", line 39, in reraise
    raise value
  File "C:\Users\anink\anaconda3\lib\site-packages\flask\app.py", line 1950, in full_dispatch_request
    rv = self.dispatch_request()
  File "C:\Users\anink\anaconda3\lib\site-packages\flask\app.py", line 1936, in dispatch_request
    return self.view_functions[rule.endpoint](**req.view_args)
  File "C:\Users\anink\anaconda3\lib\site-packages\flask_cors\decorator.py", line 130, in wrapped_function
    resp = make_response(f(*args, **kwargs))
  File "C:\Users\anink\OneDrive\Documents\books\chicken\Chicken-Disease-Classification-Projects-val\app.py", line 40, in predictRoute
    result = clApp.classifier.predict()
  File "c:\users\anink\onedrive\documents\books\chicken\chicken-disease-classification-projects-val\src\cnnClassifier\pipeline\predict.py", line 16, in predict
    model = load_model(os.path.join("artifacts","training", "model.h5"))
  File "C:\Users\anink\anaconda3\lib\site-packages\keras\src\saving\saving_api.py", line 262, in load_model
    return legacy_sm_saving_lib.load_model(
  File "C:\Users\anink\anaconda3\lib\site-packages\keras\src\utils\traceback_utils.py", line 70, in error_handler
    raise e.with_traceback(filtered_tb) from None
  File "C:\Users\anink\anaconda3\lib\site-packages\keras\src\saving\legacy\save.py", line 234, in load_model
    raise IOError(
OSError: No file or directory found at artifacts\training\model.h5
[2023-11-12 07:04:43,100: INFO: _internal: 192.168.1.216 - - [12/Nov/2023 07:04:43] "[35m[1mPOST /predict HTTP/1.1[0m" 500 -]
